Workbook

Sheet Capacidades
A1: Gestión de Dirección Empresarial
A2: Gestión de Políticas
A3: Gestión de Entidades Empresariales
A4: Gestión de Riesgos
A5: Gestión Financiera
A6: Gestión de Incidentes de Fraude
A7: Gestión de Iniciativas
A8: Gestión de Inversionistas
A9: Gestión de Acuerdos y Contratos con Clientes
A10: Gestión de Instrumentos Financieros
A11: Gestión de Planes Financieros
A12: Gestión de Portafolios de Inversión
... A47: Gestión de Integración e Interoperabilidad

Sheet Tribus
A1: TRIBU | B1: ACRONIMOS
A2: TRIBU ADMINISTRACION DE CREDITO | B2: tac | D2: =CONCATENATE(B2,"-middleware") -> tac-middleware | I2: =CONCATENATE("- "";A2,""") -> - ";A2,"
A3: TRIBU CANALES | B3: tca | D3: =CONCATENATE(B3,"-middleware") -> tca-middleware
A4: COE DATOS & ANALITICA | B4: cda | D4: =CONCATENATE(B4,"-middleware") -> cda-middleware
A5: TRIBU EMPRESAS | B5: tem | D5: =CONCATENATE(B5,"-middleware") -> tem-middleware
A6: TRIBU MEDIOS DE PAGO | B6: tmp | D6: =CONCATENATE(B6,"-middleware") -> tmp-middleware
A7: TRIBU PRODUCTOS | B7: tpr | D7: =CONCATENATE(B7,"-middleware") -> tpr-middleware
A8: TRIBU SEGMENTOS Y NEGOCIOS DIGITALES | B8: tnd | D8: =CONCATENATE(B8,"-middleware") -> tnd-middleware
A9: AREA MICROFINANZAS | B9: tmi | D9: =CONCATENATE(B9,"-middleware") -> tmi-middleware
A10: COE CIBERSEGURIDAD | B10: csg | D10: =CONCATENATE(B10,"-middleware") -> csg-middleware
A11: COE EXPERIENCIA | D11: =CONCATENATE(B11,"-middleware") -> -middleware
A12: COE LACE | D12: =CONCATENATE(B12,"-middleware") -> -middleware
A13: CHAPTER ARQUITECTURA | D13: =CONCATENATE(B13,"-middleware") -> -middleware
A14: TRIBU INFRAESTRUCTURA | D14: =CONCATENATE(B14,"-middleware") -> -middleware
A15: CONTROL_TI | D15: =CONCATENATE(B15,"-middleware") -> -middleware
A16: TRIBU AREAS DE APOYO | B16: taa | D16: =CONCATENATE(B16,"-middleware") -> taa-middleware
A17: TORRES Y SERVICIOS | D17: =CONCATENATE(B17,"-middleware") -> -middleware
A18: AREA REMESAS | B18: trm | D18: =CONCATENATE(B18,"-middleware") -> trm-middleware
A19: TRIBU CORES Y TRANSACCIONES | B19: tct | D19: =CONCATENATE(B19,"-middleware") -> tct-middleware
A20: COE DE TRANSFORMACIÓN DE PROCESOS Y AUTOMATIZACION | B20: cee | D20: =CONCATENATE(B20,"-middleware") -> cee-middleware | F20: bzp-middleware
A21: AREA TECNOLOGIA TI | D21: =CONCATENATE(B21,"-middleware") -> -middleware
A22: CASH MANAGEMENT | D22: =CONCATENATE(B22,"-middleware") -> -middleware
A23: COE ENGINEERING | D23: =CONCATENATE(B23,"-middleware") -> -middleware
A24: DEUDA TECNICA | D24: =CONCATENATE(B24,"-middleware") -> -middleware
A25: MODELO DE ATENCION | D25: =CONCATENATE(B25,"-middleware") -> -middleware
A26: TRIBU INTEGRACIONES Y NUEVAS CAPACIDADES | B26: tia | D26: =CONCATENATE(B26,"-middleware") -> tia-middleware
A27: POR ASIGNAR | D27: =CONCATENATE(B27,"-middleware") -> -middleware
A28: ECOSISTEMA | D28: =CONCATENATE(B28,"-middleware") -> -middleware
A29: Gerencia Proyectos Especiales | D29: =CONCATENATE(B29,"-middleware") -> -middleware
A30: GERENCIA ARQUITECTURA USUARIO FINAL | D30: =CONCATENATE(B30,"-middleware") -> -middleware
A31: GERENCIA SEGURIDAD APLICADA | D31: =CONCATENATE(B31,"-middleware") -> -middleware
A32: GERENCIA SRE | D32: =CONCATENATE(B32,"-middleware") -> -middleware
A33: TRIBU_DE_UNA | D33: =CONCATENATE(B33,"-middleware") -> -middleware

Sheet Puertos
A1: MULTIPROTOCOL GATEWAY | B1: PUERTOS HTTP | C1: PUERTOS HTTPS | D1: PROTOCOLO
A2: MPG_HTTPS_External_Services | B2: 7195 | C2: 9443 | D2: SOAP
A3: MPG_IIB_HTTP_SERVICES | B3: 7180 | C3: 7181 | D3: SOAP
A4: MPG_IIB_SANDBOX | B4: 7182 | C4: 7183 | D4: SOAP
A5: MPG_IIB_SANDBOX_BIMO | B5: 7190 | C5: 7191 | D5: SOAP
A6: MPG_IIB_TFGENERICO | B6: 7184 | C6: 7185 | D6: SOAP
A7: MPG_PSMDW_HTTP_SERVICES | B7: 9180 | C7: 9181 | D7: SOAP
A8: MPGW_BATCH_SOAP_TECNICOS | B8: 8935 | D8: SOAP
A9: MPGW_ESB_JSON_BALANCEO_TECNICOS | B9: 8937 | D9: REST
A10: MPGW_ESB_JSON_BALANCEO_TECNICOS | B10: 18937 | D10: REST
A11: MPGW_ESB_MQ_LOGS_JSON_TECNICOS | B11: 8936 | D11: REST
A12: MPGW_ESB_MQ_LOGS_TECNICOS | B12: 8933 | D12: REST
A13: MPGW_ESB_REST_TECNICOS | C13: 8932 | D13: REST
A14: MPGW_ESB_SOAP_BALANCEO_TECNICOS | B14: 8934 | D14: SOAP
A15: MPGW_ESB_SOAP_BALANCEO_TECNICOS | B15: 8939 | D15: SOAP
A16: MPGW_ESB_SOAP_TECNICOS | B16: 8931 | C16: 8531 | D16: SOAP
A17: MPGW_EXT_XML_WATCHLIST | C17: 7635 | D17: SOAP
A18: MPGW_EXT_SOAP_WATCHLIST | C18: 7634 | D18: SOAP
A19: MPGW_EXT_REST_WATCHLIST | C19: 7633 | D19: REST
A20: MPGW_ESB_SOAP_SOPORTE | B20: 8901 | C20: 8501 | D20: SOAP
A21: MPGW_ESB_REST_SOPORTE | C21: 8902 | D21: REST
A22: MPGW_AYS_REST_BANRED | C22: 8904 | D22: REST
A23: MPGW_ESB_REST_ADMINISTRACION | C23: 8982 | D23: REST
A24: MPGW_ESB_SOAP_ADMINISTRACION | B24: 8981 | D24: SOAP
A25: MPGW_ESB_REST_PAGOS | C25: 8972 | D25: REST
A26: MPGW_ESB_SOAP_PAGOS | B26: 8971 | D26: SOAP
A27: MPGW_ESB_REST_PRODUCTOS | C27: 8922 | D27: REST
A28: MPGW_ESB_SOAP_PRODUCTOS | B28: 8921 | D28: SOAP
A29: MPGW_ESB_REST_REGLAS | C29: 8962 | D29: REST
A30: MPGW_ESB_SOAP_REGLAS | C30: 8561 | D30: SOAP
A31: MPGW_ESB_SOAP_REGLAS | B31: 8961 | D31: SOAP
A32: MPGW_ESB_REST_SEGURIDAD | C32: 8952 | D32: REST
A33: MPGW_ESB_SOAP_SEGURIDAD | C33: 8551 | D33: SOAP
A34: MPGW_ESB_SOAP_SEGURIDAD | B34: 8951 | D34: SOAP
A35: MPGW_ESB_AAA_SOAP_SEGURIDAD | B35: 8953 | D35: SOAP
A36: MPGW_ESB_REST_TRANSFERENCIAS | C36: 8942 | D36: REST
A37: MPGW_ESB_SOAP_TRANSFERENCIAS | C37: 8541 | D37: SOAP
A38: MPGW_ESB_SOAP_TRANSFERENCIAS | B38: 8941 | D38: SOAP
A39: MPGW_ESB_REST_CLIENTES | C39: 8912 | D39: REST
A40: MPGW_ESB_SOAP_CLIENTES | B40: 8911 | C40: 8511 | D40: SOAP

Sheet Matriz a proveedor
B2: Datos a enviar al proveedor
B3: Nombre actual
B4: Descripción
B5: Nombre migrado
B6: Criticidad
B7: URL IcePanel
B8: URL WSDL
B9: URL Repositorio
B10: Protocolos
B11: Consumidores
B12: Tribu onwer

Sheet Criterios de complejidad
A1: Criterio | B1: Baja | C1: Media | D1: Alta | E1: Observación | F1: Fuente
A2: Integraciones | B2: 1 sistema | C2: 2-3 sistemas | D2: Más de 3 sistemas | E2: Cuantos backend consume el servicio? | F2: Codigo / Dynatrace
A3: Protocolos | B3: Solo SOAP o solo REST | C3: SOAP + REST o JMS | D3: Múltiples protocolos (REST, SOAP, FTP, MQ, etc.) | E3: Por cuantos protocolos es consumido el servicio? | F3: Dynatrace
A4: Transformaciones de datos | B4: Mínimas o nulas (0-1) | C4: Mapeos simples (JSON ↔ XML) Persistencia Datos (2-3) Cifrado o Encriptacion | D4: XSLT complejos, múltiples formatos Persistencia Datos (>3) Cifrado y Encriptacion | E4: Realiza transformaciones de data para consumo de algun backend?? | F4: Codigo
A5: Cache | B5: Ninguno | C5: Parcialmente | D5: Persistencia compleja | E5: Maneja guardado de información en cache obtenida desde algun backend? | F5: Codigo
A6: Volumen de datos | B6: < 50 K | C6: 50 K - 1M | D6: > 1 M | E6: Obtener numero de transacciones del servicio en dia mas transaccional desde dynatrace (recomendado quincena o fin de mes) | F6: Dynatrace
A7: Impacto en otros servicios | B7: Independiente (ORQ) (puede ser probado por la app) | C7: Afecta algunos servicios omni (WS) | D7: Altamente acoplado, impacto transversal (Servicio Generico) | E7: Es un servicio transversal o genérico? | F7: Baja para todos
A8: Consumidores | B8: 1 consumidor | C8: 2 -3 consumidores | D8: mas de 3 consumidores | E8: Cuantas aplicaciones consumen el servicio? | F8: Dynatrace / Logs
A9: Interacción con proveedores externos | B9: Ninguno | C9: 1 proveedor | D9: 2 o mas proveedores | E9: El servicio es consumido o consume algun servicio de proveedor? Banred, interdin, otros | F9: Dynatrace / Código
A10: Metodos que expone | B10: 1 metodo | C10: 2 -3 metodos | D10: Más de 3 metodos | E10: Metodos que expone el servicio | F10: Dynatrace / Código

Sheet Validacion de servicios
A1: Servicio | B1: Nuevo nombre | C1: Descripción / Funcionalidad | D1: TRIBU | E1: ACRONIMO | F1: Tecnologia | G1: Tipo | H1: Estado del análisis | I1: Estado del servicio | J1: Integraciones / Consume | K1: Tecnologia del backend | L1: Tecnologia para despliegue de servicio migrado | M1: # Integraciones | N1: Peso | O1: Protocolos de consumo | P1: # Protocolos | Q1: Peso | R1: Transformaciones de datos | S1: # de transformaciones | T1: Peso | U1: Cache Adicional al config | V1: Archivo o servicio de donde obtiene informacion para cache | W1: Peso | X1: Volumen de datos / Request | Y1: Volumen de datos / Response time | Z1: TPM promedio (rango 2 horas) | AA1: TPM hora pico (rango 2 horas) | AB1: Peso | AC1: Impacto en otros servicios | AD1: Peso | AE1: Tribu consumidor | AF1: Consumidores / Servicios | AG1: Consumidores / Sitios | AH1: # de consumidores | AI1: Peso | AJ1: Interacción con proveedores externos | AK1: Peso | AL1: Metodos que expone | AM1: Peso | AN1: Peso del servicio | AO1: Complejidad del servicio | AP1: Proveedor que migrara el servicio | AQ1: Observación Discovery | AR1: Priorizacion | AS1: LINK ICEPANEL | AT1: LINK WSDL | AU1: LINK CODIGO | AV1: OLA | AW1: Consumen tecnologia deprecada
A2: ORQClientes0002 | B2: =CONCATENATE(LOWER(E2),"-msa-sp-",LOWER(A2)) -> tnd-msa-sp-orqclientes0002 | C2: Consulta información básica del cliente | D2: TRIBU SEGMENTOS Y NEGOCIOS DIGITALES | E2: =VLOOKUP(D2,Tribus!$A$1:$B$33,2,FALSE) -> tnd | F2: Bus Omnicanalidad | G2: ORQ | H2: Completado | I2: A Desarrollo | J2: WSTecnicos0036 (ConsultarDetalleTransaccionDelay03) - umptecnicos0111 (ConsultarDetalleTransaccionDelayCTServicio) -> BDD: PPOMNICA ESQUEMA: TRANESPERA TABLA: OMN_TRA_TRANSACCION_ESPERA WSTecnicos0006 (ConsultarAtributosTransaccion01) -> UMPTransferencias0001 (ValidarCupoCanalTransferencia51) -> TX031967 (Validación de cupo sobre cuenta para transferencias en la Banca Electrónica.) -> UMPTecnicos0025 (ConsultarDetallesEntidadFinanciera01) -> URL WAS http://10.151.8.62:8934/Omnicanalidad/AplicationServer/WSTecnicos0008 (Consulta detalles entidad financiera) -> UMPProductos0045 (ConsultarCobroReferenciaBancaria01) -> TX000503 (Consulta de cobro referencia bancaria.) WSClientes0024 (ConsultarIdentificacion01) -> UMPClientes0002 (ConsultarInformacionBasica01) -> TX060480 (Consulta datos de contacto para cliente de BEP e información básica) -> UMPClientes0181 (ConsultarInformacionBasicaOPS01) -> URL OCP https://mdw-msa-sp-tmp-customer-enp.apps.ocptest.uiotest.bpichinchatest.test/PartyReferenceDataDirectory/Reference/Retrieve (ConsultarInformacionBasicaOPS01) WSClientes0007 (ConsultarContactoTransaccional01) -> UMPClientes0002 (ConsultarInformacionBasica01) -> TX060480 (Consulta datos de contacto para cliente de BEP e información básica) -> UMPClientes0028 (ConsultarIdentificacion01) NO SE USA -> UMPClientes0003 (ConsultarContactoNotificacion01) -> TX067186 (Consulta datos de contacto para cliente de BEP e información básica) -> UMPClientes0020 (ConsultaInformacionCliente01) -> TX067050 (Consulta información basica del cliente mediante TX067050.) -> UMPClientes0005 (ActualizarContactoTransaccional31) -> TX067186 (Actualiza datos del contacto transaccional) WSClientes0006 (ConsultarInformacionBasica01) -> UMPClientes0020 (ConsultaInformacionCliente01) -> TX067050 (Consulta información basica del cliente mediante TX067050.) -> UMPTecnicos0006 (ConsultarTransaccionCatalogo01) -> TX079006 (Consultar TX de catalogo: ciudad, nacionalidad, agencia) -> UMPClientes0042 (ConsultarReferencia01) -> TX062120 (Consulta de Cuentas del cliente en Bancs) | K2: Bus Omnicanalidad Was Omnicanalidad | L2: ON-PREMISE | M2: 5 | N2: Alta | O2: api 8912 api - 443 - https://apis.pichincha.com/support/apigee/orqclientes0002/v1/api/customers-persons-contact-points/retrieve (APIM) -> datapowr interno api - 443 - https://api.pichincha.com/sda/tcs/ORQClientes0002 (APIGEE) -> datapower externo | P2: REST SOAP | Q2: Media | R2: Ninguna | S2: 0 | T2: Baja | U2: Almacena información de backend en cache obteniendo del WSTecnicos0006 para atributos de la tansaccion | V2: WSTecnicos0006 | W2: Media | X2: 129K | Y2: 202ms | AB2: Media | AC2: Si puede ser probado por las app | AD2: Baja | AE2: TRIBU CANALES TRIBU MEDIOS DE PAGO TRIBU PRODUCTOS TRIBU SEGMENTOS Y NEGOCIOS DIGITALES | AF2: APIM sda-msa-bank-certificates;CertificateController tdd-msa-card;CustomerAddressController crd-msa-customer-integration;CustomerIntegrationController tdd-msa-card;DebitCardRequestController bmo-msa-core-account-client-name;ClientNameController mht-msa-user-profile;ClientInformationController | AG2: 0 | AH2: 5 | AI2: Alta | AJ2: Ninguno | AK2: Baja | AL2: ConsultaInformacionBasicaCliente01 | AM2: Baja | AN2: =IFERROR(SUM(CHOOSE(MATCH(N2,{"Baja";"Media";"Alta"},0),1,2,3), CHOOSE(MATCH(Q2,{"Baja";"Media";"Alta"},0),1,2,3), CHOOSE(MATCH(T2,{"Baja";"Media";"Alta"},0),1,2,3), CHOOSE(MATCH(W2,{"Baja";"Media";"Alta"},0),1,2,3), CHOOSE(MATCH(AB2,{"Baja";"Media";"Alta"},0),1,2,3), CHOOSE(MATCH(AD2,{"Baja";"Media";"Alta"},0),1,2,3), CHOOSE(MATCH(AI2,{"Baja";"Media";"Alta"},0),1,2,3), CHOOSE(MATCH(AK2,{"Baja";"Media";"Alta"},0),1,2,3), CHOOSE(MATCH(AM2,{"Baja";"Media";"Alta"},0),1,2,3)),0) -> 16 | AO2: =IF(AN2=0,"Pendiente",IF(AN2<=15,"Bajo",IF(AN2<=21,"Medio","Alto"))) -> Medio | AR2: =VLOOKUP(A2,#REF!,2,FALSE) -> #REF! | AS2: https://app.icepanel.io/landscapes/w71QNHgfDvF79GrSuA3r/versions/latest/diagrams/editor?diagram=hhqQHHJSsg&model=sgwrn80kg0j&overlay_tab=tags&x1=-301.6&y1=-192&x2=1697.6&y2=832 | AT2: https://dev.azure.com/BancoPichinchaEC/adi-especificaciones-tecnicas/_git/adi-doc-tecspec-tribu-integracion-apis?version=GBmaster&path=/sp%20-%20Soporte/tnd-msa-sp-orqclientes0002 | AU2: https://dev.azure.com/BancoPichinchaEC/tpl-bus-omnicanal/_git/sqb-msa-orqclientes0002 | AV2: 1 | AW2: PCBG-545
A3: ORQClientes0003 | B3: =CONCATENATE(LOWER(E3),"-msa-sp-",LOWER(A3)) -> tpr-msa-sp-orqclientes0003 | C3: Orquestador que permite realizar la consulta de la posición consolidada de clientes. | D3: TRIBU PRODUCTOS | E3: =VLOOKUP(D3,Tribus!$A$1:$B$33,2,FALSE) -> tpr | F3: Bus Omnicanalidad | G3: ORQ | H3: Completado | I3: A Desarrollo | J3: WSClientes0024 --> ConsultarIdentificacion01 WSProductos0024 --> ConsultarDescripcionTodosProductos01 WSProductos0023 --> ConsultarConfiguracionProducto01 WSClientes0114 --> ConsultaCuentasCliente02 WSClientes0002 --> consultarPrestamosActivos01 ays-msa-dm-wsclientes0220 --> api/v1/Tarjetas/ConsultarTarjetas01 WSClientes0003 --> ConsultarTarjetasActivas01 WSProductos0123 --> consultarCatalogoTarjeta02 WSProductos0118 --> consultarClienteInterdin02 | K3: Bus Omnicanalidad Was Omnicanalidad openshift | L3: ON-PREMISE | M3: 9 | N3: Alta | O3: SOAP | P3: 1 | Q3: Baja | R3: Mapeo hacia servicio de consulta de tarjetas de OPS | S3: 1 | T3: Media | U3: Almacena archivos de parametros y catalogos en cache path: configuraciones/301000301.xml | V3: configuraciones/301000301.xml | W3: Alta | X3: 11.9M | Y3: 181ms | AB3: Alta | AC3: Si puede ser probado por las app | AD3: Baja | AE3: TRIBU MEDIOS DE PAGO TRIBU EMPRESAS TRIBU PRODUCTOS TRIBU CANALES COE_TRANSFORMACION_PROCESOS | AF3: APIM tdd-msa-card;AccountClientController omn-msa-account-balance;AccountController inv-msa-investments;AccountsController app-balance-by-type-account;AccountBalanceByTypeController app-transaction-balance;TransactionBalanceController bbe-msa-sp-account sda-msa-payments;BillPaymentsController omn-msa-account-balance;CreditCardController tdd-msa-card;DebitCardRequestController sge-msa-ux-insurance;HubController sda-msa-payments;ListFavoritesController one-msa-sp-customer-product sda-msa-payments;ProductSummaryController bbe-msa-bs-loan bbe-msa-sp-credit-card app-transaction-balance;TransactionBalanceController omn-msa-account-balance;ProductSummaryController sda-msa-payments;BillPaymentsController sda-msa-payments;PaymentFavoritesController sge-msa-insurance;InsuranceControllerImpl | AG3: Default Web Site:443,8043 (/BPMPichinchaSG) Default Web Site:80,8080 (/WApi_NetManager_CNB_MPagos) | AH3: 23 | AI3: Alta | AJ3: Interdin - Optar Integrador | AK3: Alta | AL3: ConsultarProductosActivos01 | AM3: Baja | AN3: =IFERROR(SUM(CHOOSE(MATCH(N3,{"Baja";"Media";"Alta"},0),1,2,3), CHOOSE(MATCH(Q3,{"Baja";"Media";"Alta"},0),1,2,3), CHOOSE(MATCH(T3,{"Baja";"Media";"Alta"},0),1,2,3), CHOOSE(MATCH(W3,{"Baja";"Media";"Alta"},0),1,2,3), CHOOSE(MATCH(AB3,{"Baja";"Media";"Alta"},0),1,2,3), CHOOSE(MATCH(AD3,{"Baja";"Media";"Alta"},0),1,2,3), CHOOSE(MATCH(AI3,{"Baja";"Media";"Alta"},0),1,2,3), CHOOSE(MATCH(AK3,{"Baja";"Media";"Alta"},0),1,2,3), CHOOSE(MATCH(AM3,{"Baja";"Media";"Alta"},0),1,2,3)),0) -> 20 | AO3: =IF(AN3=0,"Pendiente",IF(AN3<=15,"Bajo",IF(AN3<=21,"Medio","Alto"))) -> Medio | AR3: =VLOOKUP(A3,#REF!,2,FALSE) -> #REF! | AS3: https://s.icepanel.io/wJSECZOwwNkkW8/Rqyj | AT3: https://dev.azure.com/BancoPichinchaEC/adi-especificaciones-tecnicas/_git/adi-doc-tecspec-tribu-integracion-apis?path=/sp%20-%20Soporte/tpr-msa-sp-orqclientes0003 | AU3: sqb-msa-orqclientes0003 - Repos | AV3: 1 | AW3: https://pichincha.atlassian.net/browse/PCBG-654
A4: ORQClientes0004 | B4: =CONCATENATE(LOWER(E4),"-msa-sp-",LOWER(A4)) -> tnd-msa-sp-orqclientes0004 | C4: Microservicio que actualiza contacto transaccional | D4: TRIBU SEGMENTOS Y NEGOCIOS DIGITALES | E4: =VLOOKUP(D4,Tribus!$A$1:$B$33,2,FALSE) -> tnd | F4: Bus Omnicanalidad | G4: ORQ | H4: Completado | I4: A Desarrollo | J4: WSClientes0020 -> ActualizarContactoTransaccional31 WSClientes0024 -> ConsultarIdentificacion01 WSClientes0028 -> ConsultarClientePagosPichincha01, ActualizarClientePagosPichincha32 WSClientes0030 -> ConsultarContactoNotificacion01 WSProductos0015 -> ConsultarClientePichinchaCelular01, ActualizarClientePichinchaCelular32 WSSeguridad0020 -> consultarAfiliado01, actualizarInformacion33, actualizarEstadoClienten34 | K4: Bus Omnicanalidad Was Omnicanalidad | L4: ON-PREMISE | M4: 6 | N4: Alta | O4: REST SOAP | P4: 2 | Q4: Media | R4: Ninguna | S4: 0 | T4: Baja | U4: Ninguna | W4: Baja | X4: 455 | Y4: 339ms | AB4: Baja | AC4: Si puede ser probado por las app | AD4: Baja | AE4: TRIBU CANALES | AF4: Ninguno | AG4: Segun BDD: 00352 - Portal Empresarial_BPM | AH4: 1 | AI4: Baja | AJ4: Ninguno | AK4: Baja | AL4: ActualizarContactoTransaccional31 | AM4: Baja | AN4: =IFERROR(SUM(CHOOSE(MATCH(N4,{"Baja";"Media";"Alta"},0),1,2,3), CHOOSE(MATCH(Q4,{"Baja";"Media";"Alta"},0),1,2,3), CHOOSE(MATCH(T4,{"Baja";"Media";"Alta"},0),1,2,3), CHOOSE(MATCH(W4,{"Baja";"Media";"Alta"},0),1,2,3), CHOOSE(MATCH(AB4,{"Baja";"Media";"Alta"},0),1,2,3), CHOOSE(MATCH(AD4,{"Baja";"Media";"Alta"},0),1,2,3), CHOOSE(MATCH(AI4,{"Baja";"Media";"Alta"},0),1,2,3), CHOOSE(MATCH(AK4,{"Baja";"Media";"Alta"},0),1,2,3), CHOOSE(MATCH(AM4,{"Baja";"Media";"Alta"},0),1,2,3)),0) -> 12 | AO4: =IF(AN4=0,"Pendiente",IF(AN4<=15,"Bajo",IF(AN4<=21,"Medio","Alto"))) -> Bajo | AR4: =VLOOKUP(A4,#REF!,2,FALSE) -> #REF! | AS4: https://app.icepanel.io/landscapes/w71QNHgfDvF79GrSuA3r/versions/latest/diagrams/editor?diagram=C7BopaQBkK&model=IpbKqE7HWq&overlay_tab=tags&x1=0&y1=0&x2=1272&y2=564 | AT4: https://dev.azure.com/BancoPichinchaEC/adi-especificaciones-tecnicas/_git/adi-doc-tecspec-tribu-integracion-apis?version=GBmaster&path=/sp%20-%20Soporte/tnd-msa-sp-orqclientes0004 | AU4: https://dev.azure.com/BancoPichinchaEC/tpl-bus-omnicanal/_git/sqb-msa-orqclientes0004 | AV4: 1 | AW4: https://pichincha.atlassian.net/browse/PCBG-583
A5: ORQClientes0005 | B5: =CONCATENATE(LOWER(E5),"-msa-sp-",LOWER(A5)) -> csg-msa-sp-orqclientes0005 | C5: Servicio que actualiza preferencia de notificación para segundo factor de autenticación (OTP, Clave Dinámica) en BDD | D5: COE CIBERSEGURIDAD | E5: =VLOOKUP(D5,Tribus!$A$1:$B$33,2,FALSE) -> csg | F5: Bus Omnicanalidad | G5: ORQ | H5: Completado | I5: A Desarrollo | J5: WSClientes0024 --> ConsultarIdentificacion01 WSClientes0006 --> ConsultarInformacionBasica01 WSTecnicos0039 --> actualizarNotificacionesPorCliente31 WSClientes0010 --> consultarGrupoClaveDigital01 WSClientes0026 --> consultar02 WSClientes0026 --> registrar23 WSClientes0026 --> incrementar34 | K5: Bus Omnicanalidad Was Omnicanalidad | L5: ON-PREMISE | M5: 7 | N5: Alta | O5: SOAP | P5: 1 | Q5: Baja | R5: Si, existe cifrado mediante TCSProvider previo al llamado de servicios | S5: 1 | T5: Media | U5: Ninguna | W5: Baja | X5: 2.33k | Y5: 180ms | AB5: Baja | AC5: Si puede ser probado por las app | AD5: Baja | AE5: TRIBU CANALES | AF5: Se consume operativamente desde el Administrador Omnicanal | AG5: Administrador Omnicanal | AH5: 1 | AI5: Baja | AJ5: Ninguno | AK5: Baja | AL5: ActualizarMedioNotificacionCliente31 | AM5: Baja | AN5: =IFERROR(SUM(CHOOSE(MATCH(N5,{"Baja";"Media";"Alta"},0),1,2,3), CHOOSE(MATCH(Q5,{"Baja";"Media";"Alta"},0),1,2,3), CHOOSE(MATCH(T5,{"Baja";"Media";"Alta"},0),1,2,3), CHOOSE(MATCH(W5,{"Baja";"Media";"Alta"},0),1,2,3), CHOOSE(MATCH(AB5,{"Baja";"Media";"Alta"},0),1,2,3), CHOOSE(MATCH(AD5,{"Baja";"Media";"Alta"},0),1,2,3), CHOOSE(MATCH(AI5,{"Baja";"Media";"Alta"},0),1,2,3), CHOOSE(MATCH(AK5,{"Baja";"Media";"Alta"},0),1,2,3), CHOOSE(MATCH(AM5,{"Baja";"Media";"Alta"},0),1,2,3)),0) -> 12 | AO5: =IF(AN5=0,"Pendiente",IF(AN5<=15,"Bajo",IF(AN5<=21,"Medio","Alto"))) -> Bajo | AQ5: Considerar que el servicio se utilizaba para validar factor de autenticación al inicio de la clave digital, se debe validar si su logica se sigue usando de lo contratio se debe deprecar | AR5: =VLOOKUP(A5,#REF!,2,FALSE) -> #REF! | AS5: https://s.icepanel.io/wJSECZOwwNkkW8/geiS | AT5: https://dev.azure.com/BancoPichinchaEC/adi-especificaciones-tecnicas/_git/adi-doc-tecspec-tribu-integracion-apis?version=GBmaster&path=/sp%20-%20Soporte/csg-msa-sp-orqclientes0005 | AU5: sqb-msa-orqclientes0005 - Repos | AV5: 1 | AW5: https://pichincha.atlassian.net/browse/PCBG-584
A6: ORQClientes0007 | B6: =CONCATENATE(LOWER(E6),"-msa-sp-",LOWER(A6)) -> tpr-msa-sp-orqclientes0007 | C6: Servicio que actualiza cupo de cuentas del cliente | D6: TRIBU PRODUCTOS | E6: =VLOOKUP(D6,Tribus!$A$1:$B$33,2,FALSE) -> tpr | F6: Bus Omnicanalidad | G6: ORQ | H6: Completado | I6: A Desarrollo | J6: WSClientes0114 WSProductos0009 CE_EVENTOS | K6: Bus Omnicanalidad | L6: ON-PREMISE | M6: 1 | N6: Baja | O6: SOAP | P6: 1 | Q6: Baja | R6: Ninguna | S6: 0 | T6: Baja | U6: Parcialmente. path: configuraciones/000000001.xml | V6: configuraciones/000000001.xml | W6: Media | X6: 5.54K | Y6: 188ms | AB6: Baja | AC6: Puede ser consumido por apps. | AD6: Baja | AE6: TRIBU_CANALES | AF6: ORQTecnicos0003 (Invoca servicios asyncronos) | AG6: Segun BDD 00663 -> Banca Movil 00647 -> Banca Web | AH6: 2 | AI6: Media | AJ6: Ninguno | AK6: Baja | AL6: ActualizarCupoCuentaTransaccion31 | AM6: Baja | AN6: =IFERROR(SUM(CHOOSE(MATCH(N6,{"Baja";"Media";"Alta"},0),1,2,3), CHOOSE(MATCH(Q6,{"Baja";"Media";"Alta"},0),1,2,3), CHOOSE(MATCH(T6,{"Baja";"Media";"Alta"},0),1,2,3), CHOOSE(MATCH(W6,{"Baja";"Media";"Alta"},0),1,2,3), CHOOSE(MATCH(AB6,{"Baja";"Media";"Alta"},0),1,2,3), CHOOSE(MATCH(AD6,{"Baja";"Media";"Alta"},0),1,2,3), CHOOSE(MATCH(AI6,{"Baja";"Media";"Alta"},0),1,2,3), CHOOSE(MATCH(AK6,{"Baja";"Media";"Alta"},0),1,2,3), CHOOSE(MATCH(AM6,{"Baja";"Media";"Alta"},0),1,2,3)),0) -> 11 | AO6: =IF(AN6=0,"Pendiente",IF(AN6<=15,"Bajo",IF(AN6<=21,"Medio","Alto"))) -> Bajo | AQ6: Interactua con el MQ , lee mensaje | AR6: =VLOOKUP(A6,#REF!,2,FALSE) -> #REF! | AS6: https://s.icepanel.io/wJSECZOwwNkkW8/PkZD | AT6: https://dev.azure.com/BancoPichinchaEC/adi-especificaciones-tecnicas/_git/adi-doc-tecspec-tribu-integracion-apis?path=/sp%20-%20Soporte/tpr-msa-sp-orqclientes0007 | AU6: https://dev.azure.com/BancoPichinchaEC/tpl-bus-omnicanal/_git/sqb-msa-orqclientes0007?path=/com/bpichincha/esb/orqclientes0007/ActualizarCupoCuentaTransaccion31.esql | AV6: 1 | AW6: https://pichincha.atlassian.net/browse/PCBG-585
A7: ORQClientes0008 | B7: =CONCATENATE(LOWER(E7),"-msa-sp-",LOWER(A7)) -> tnd-msa-sp-orqclientes0008 | C7: Consultar detalle del cliente | D7: TRIBU SEGMENTOS Y NEGOCIOS DIGITALES | E7: =VLOOKUP(D7,Tribus!$A$1:$B$33,2,FALSE) -> tnd | F7: Bus Omnicanalidad | G7: ORQ | H7: Completado | I7: A Desarrollo | J7: WSClientes0024 -> ConsultarIdentificacion01 WSClientes0037 -> ConsultarClienteRegistroCivil01 WSClientes0038 -> ConsultarDetalleAdicionalesCliente01 / opc 5 / 21 / 1 / WSTecnicos0063 -> obtenerCatalogosSigloBancs01 | K7: Bus Omnicanalidad Was Omnicanalidad | L7: ON-PREMISE | M7: 4 | N7: Alta | O7: REST - datapowerexterno SOAP | P7: 2 | Q7: Media | R7: Ninguna | S7: 0 | T7: Baja | U7: Nacionalidades. Consumido de WSTecnicos0063 | V7: WSTecnicos0063 | W7: Media | X7: 9.96K | Y7: 310ms | AB7: Baja | AC7: Si puede ser probado por las app | AD7: Baja | AE7: AREA MICROFINANZAS | AF7: https://serviciosexternos.pichincha.com:8445/BPMicrofinanzasProd/Servicios/Rest/FlexibleUpdateWorkOrder | AG7: Segun BDD: Microfinanzas - 00650 | AH7: 1 | AI7: Baja | AJ7: ninguno | AK7: Baja | AL7: ConsultarDetalleCliente01 | AM7: Baja | AN7: =IFERROR(SUM(CHOOSE(MATCH(N7,{"Baja";"Media";"Alta"},0),1,2,3), CHOOSE(MATCH(Q7,{"Baja";"Media";"Alta"},0),1,2,3), CHOOSE(MATCH(T7,{"Baja";"Media";"Alta"},0),1,2,3), CHOOSE(MATCH(W7,{"Baja";"Media";"Alta"},0),1,2,3), CHOOSE(MATCH(AB7,{"Baja";"Media";"Alta"},0),1,2,3), CHOOSE(MATCH(AD7,{"Baja";"Media";"Alta"},0),1,2,3), CHOOSE(MATCH(AI7,{"Baja";"Media";"Alta"},0),1,2,3), CHOOSE(MATCH(AK7,{"Baja";"Media";"Alta"},0),1,2,3), CHOOSE(MATCH(AM7,{"Baja";"Media";"Alta"},0),1,2,3)),0) -> 13 | AO7: =IF(AN7=0,"Pendiente",IF(AN7<=15,"Bajo",IF(AN7<=21,"Medio","Alto"))) -> Bajo | AR7: =VLOOKUP(A7,#REF!,2,FALSE) -> #REF! | AS7: https://s.icepanel.io/wJSECZOwwNkkW8/s2K8 | AT7: https://dev.azure.com/BancoPichinchaEC/adi-especificaciones-tecnicas/_git/adi-doc-tecspec-tribu-integracion-apis?path=/sp%20-%20Soporte/tnd-msa-sp-orqclientes0008 | AU7: https://dev.azure.com/BancoPichinchaEC/tpl-bus-omnicanal/_git/sqb-msa-orqclientes0008 | AV7: 1 | AW7: https://pichincha.atlassian.net/browse/PCBG-586
A8: ORQClientes0016 | B8: =CONCATENATE(LOWER(E8),"-msa-sp-",LOWER(A8)) -> tnd-msa-sp-orqclientes0016 | C8: Orquestar las consultas para obtener la informacion complementaria del cliente | D8: TRIBU SEGMENTOS Y NEGOCIOS DIGITALES | E8: =VLOOKUP(D8,Tribus!$A$1:$B$33,2,FALSE) -> tnd | F8: Bus Omnicanalidad | G8: ORQ | H8: Completado | I8: A Desarrollo | J8: ORQClientes0016 WSClientes0060 (informacionAdicionalClienteSFI01 - WAS) -> UMPClientes0075 (OperacionInformacionComplementariaCliente51) -> UMPClientes0075 (ObtenerInformacionAdicionalClienteSFI) -> BDD: CREDIFE, SP: CFE_INFCOMPL_MVL(?,?) WSClientes0060 (OperacionDatosComplementariosCliente51 - IIB) -> UMPClientes0075 (OperacionInformacionComplementariaCliente51) -> TX067145 (Consultar informacion complentaria del cliente) WSClientes0038 (OperacionEconomicosCliente52) -> UMPClientes0020 (ConsultaInformacionCliente01) -> TX067050 (opc 1, 5, 15, 21) -> UMPClientes0061 (ActualizarInfAdicionalCliente31) -> TX067118 -> UMPClientes0057 (ActualizarInformacionCliente31) -> TX067116 WSClientes0055 (OperacionActividadEconomicaCliente51) -> UMPClientes0069 (Consulta actividad economica) -> TX67196 -> UMPClientes0066 (Consulta Correspondencia (localizacion)) -> TX062120 WSClientes0061 (OperacionDemograficosCliente51) -> UMPClientes0077 (OperacionDemograficosCliente51) -> TX061406 WSClientes0062 (OperacionIdentificacionCliente51) - UMPClientes0078 (OperacionIdentificacionCliente51 )-> TX067153 -> Consulta información de identificación del cliente WSClientes0099 (OperacionLocalizacion51) -> UMPClientes0064 - OperacionLocalizacion51 - TX061404 - Consulta la direccion de un cliente -> UMPClientes0065 - OperacionGeolocalizacion51 - TX062130 - Consulta la geolocalizacion de un cliente WSClientes0007 (ConsultarContactoTransaccional01) -> UMPClientes0002 -> ConsultarInformacionBasica01 -> TX060480 -> Consulta el CIF del cliente UMPClientes0028 -> ConsultarIdentificacion01 -> http://10.151.8.62:8934/Omnicanalidad/AplicationServer/WSClientes0045 -> Consulta identificacion cliente UMPClientes0020 -> ConsultaInformacionCliente01 -> 067050 -> Consulta información basica del cliente UMPClientes0003 -> ConsultarContactoNotificacion01 -> TX067186 -> Consulta contacto transaccional del cliente UMPClientes0005 -> ActualizarContactoTransaccional31 -> TX067186 -> Actualizar el contacto transaccional del cliente WSTecnicos0063 (obtenerCatalogosSigloBancs01) -> umptecnicos0066 (obtenerCatalogosSigloBean) -> Consulta de catalogos a BANCS , CREDIFE y S21 | K8: Bus Omnicanalidad Was Omnicanalidad | L8: ON-PREMISE | M8: 8 | N8: Alta | O8: REST - datapowerexterno SOAP | P8: 2 | Q8: Media | R8: Ninguna | S8: 0 | T8: Baja | U8: Almacena información de backend en cache, consumiendo WSTecnicos0063 | V8: WSTecnicos0063 | W8: Media | X8: 4.58K | Y8: 529ms | AB8: Baja | AC8: Si puede ser probado por las app | AD8: Baja | AE8: AREA MICROFINANZAS | AF8: https://serviciosexternos.pichincha.com:8445/BPMicrofinanzasProd/Servicios/Rest/FlexibleUpdateWorkOrder | AG8: Segun BDD: 00650 - Microfinanzas | AH8: - | AI8: Baja | AJ8: Ninguno | AK8: Baja | AL8: InformacionComplementariaCliente01 | AM8: Baja | AN8: =IFERROR(SUM(CHOOSE(MATCH(N8,{"Baja";"Media";"Alta"},0),1,2,3), CHOOSE(MATCH(Q8,{"Baja";"Media";"Alta"},0),1,2,3), CHOOSE(MATCH(T8,{"Baja";"Media";"Alta"},0),1,2,3), CHOOSE(MATCH(W8,{"Baja";"Media";"Alta"},0),1,2,3), CHOOSE(MATCH(AB8,{"Baja";"Media";"Alta"},0),1,2,3), CHOOSE(MATCH(AD8,{"Baja";"Media";"Alta"},0),1,2,3), CHOOSE(MATCH(AI8,{"Baja";"Media";"Alta"},0),1,2,3), CHOOSE(MATCH(AK8,{"Baja";"Media";"Alta"},0),1,2,3), CHOOSE(MATCH(AM8,{"Baja";"Media";"Alta"},0),1,2,3)),0) -> 13 | AO8: =IF(AN8=0,"Pendiente",IF(AN8<=15,"Bajo",IF(AN8<=21,"Medio","Alto"))) -> Bajo | AR8: =VLOOKUP(A8,#REF!,2,FALSE) -> #REF! | AS8: https://app.icepanel.io/landscapes/w71QNHgfDvF79GrSuA3r/versions/latest/diagrams/editor?diagram=uV2Jon7cnA&model=TBYWzEmBgJ&overlay_tab=tags&x1=-301.6&y1=-192&x2=1697.6&y2=832 | AT8: https://dev.azure.com/BancoPichinchaEC/adi-especificaciones-tecnicas/_git/adi-doc-tecspec-tribu-integracion-apis?path=/sp%20-%20Soporte/tnd-msa-sp-orqclientes0016 | AU8: https://dev.azure.com/BancoPichinchaEC/tpl-bus-omnicanal/_git/sqb-msa-orqclientes0016 | AV8: 1 | AW8: https://pichincha.atlassian.net/browse/PCBG-587
A9: ORQClientes0017 | B9: =CONCATENATE(LOWER(E9),"-msa-sp-",LOWER(A9)) -> tpr-msa-sp-orqclientes0017 | C9: Consultar Productos del Cliente | D9: TRIBU PRODUCTOS | E9: =VLOOKUP(D9,Tribus!$A$1:$B$33,2,FALSE) -> tpr | F9: Bus Omnicanalidad | G9: ORQ | H9: Completado | I9: A Desarrollo | J9: WSClientes0002 WSClientes0038 WSClientes0067 WSClientes0080 WSProductos0082 WSSeguridad0029 WSTecnicos0063 | K9: Bus Omnicanalidad Was Omnicanalidad | L9: ON-PREMISE | M9: 7 | N9: Alta | O9: REST - datapowerexterno SOAP | P9: 2 | Q9: Baja | R9: Ninguna | S9: 0 | T9: Baja | U9: Ninguna | W9: Baja | X9: 13.64K | Y9: 317ms | AB9: Baja | AC9: Si puede ser probado por las app | AD9: Baja | AE9: AREA MICROFINANZAS | AF9: https://serviciosexternos.pichincha.com:8445/BPMicrofinanzasProd/Servicios/Rest/FlexibleUpdateWorkOrder | AG9: Segun BDD: 00650 - Microfinanzas | AH9: 1 | AI9: Baja | AJ9: Ninguno | AK9: Baja | AL9: ConsultarProductosClientes01 | AM9: Baja | AN9: =IFERROR(SUM(CHOOSE(MATCH(N9,{"Baja";"Media";"Alta"},0),1,2,3), CHOOSE(MATCH(Q9,{"Baja";"Media";"Alta"},0),1,2,3), CHOOSE(MATCH(T9,{"Baja";"Media";"Alta"},0),1,2,3), CHOOSE(MATCH(W9,{"Baja";"Media";"Alta"},0),1,2,3), CHOOSE(MATCH(AB9,{"Baja";"Media";"Alta"},0),1,2,3), CHOOSE(MATCH(AD9,{"Baja";"Media";"Alta"},0),1,2,3), CHOOSE(MATCH(AI9,{"Baja";"Media";"Alta"},0),1,2,3), CHOOSE(MATCH(AK9,{"Baja";"Media";"Alta"},0),1,2,3), CHOOSE(MATCH(AM9,{"Baja";"Media";"Alta"},0),1,2,3)),0) -> 11 | AO9: =IF(AN9=0,"Pendiente",IF(AN9<=15,"Bajo",IF(AN9<=21,"Medio","Alto"))) -> Bajo | AR9: =VLOOKUP(A9,#REF!,2,FALSE) -> #REF! | AS9: https://s.icepanel.io/wJSECZOwwNkkW8/zJIi | AT9: https://dev.azure.com/BancoPichinchaEC/adi-especificaciones-tecnicas/_git/adi-doc-tecspec-tribu-integracion-apis?path=/sp%20-%20Soporte/tpr-msa-sp-orqclientes0017 | AU9: https://dev.azure.com/BancoPichinchaEC/tpl-bus-omnicanal/_git/sqb-msa-orqclientes0017 | AV9: 1 | AW9: https://pichincha.atlassian.net/browse/PCBG-588
A10: ORQClientes0019 | B10: =CONCATENATE(LOWER(E10),"-msa-sp-",LOWER(A10)) -> tnd-msa-sp-orqclientes0019 | C10: Consultar Datos Economicos Cliente | D10: TRIBU SEGMENTOS Y NEGOCIOS DIGITALES | E10: =VLOOKUP(D10,Tribus!$A$1:$B$33,2,FALSE) -> tnd | F10: Bus Omnicanalidad | G10: ORQ | H10: Completado | I10: A Desarrollo | J10: WSClientes0024 -> ConsultarIdentificacion01 WSClientes0038 -> OperacionEconomicosCliente52 WSClientes0071 -> AsignarInformacionBienes01 WSClientes0072 -> ActualizarDatosReferencias31 WSClientes0074 -> ActualizarDatosActividadEconomica31 | K10: Bus Omnicanalidad | L10: ON-PREMISE | M10: 5 | N10: Alta | O10: 8511 - SOAP | P10: 1 | Q10: Baja | R10: Ninguna | S10: 0 | T10: Baja | U10: Ninguna | W10: Baja | X10: 876 | Y10: 418ms | AB10: Baja | AC10: Si puede ser probado por las app | AD10: Baja | AE10: COE_TRANSFORMACION_PROCESOS | AF10: Ninguno | AG10: Default Web Site:443,8043 (/BPMPichincha) Default Web Site:443,8043 (/BPMPichinchaCH) Default Web Site:443,8043 (/BPMPichinchaCP) | AH10: 3 | AI10: Media | AJ10: Ninguno | AK10: Baja | AL10: ConsultarDatosEconomicosCliente01 | AM10: Baja | AN10: =IFERROR(SUM(CHOOSE(MATCH(N10,{"Baja";"Media";"Alta"},0),1,2,3), CHOOSE(MATCH(Q10,{"Baja";"Media";"Alta"},0),1,2,3), CHOOSE(MATCH(T10,{"Baja";"Media";"Alta"},0),1,2,3), CHOOSE(MATCH(W10,{"Baja";"Media";"Alta"},0),1,2,3), CHOOSE(MATCH(AB10,{"Baja";"Media";"Alta"},0),1,2,3), CHOOSE(MATCH(AD10,{"Baja";"Media";"Alta"},0),1,2,3), CHOOSE(MATCH(AI10,{"Baja";"Media";"Alta"},0),1,2,3), CHOOSE(MATCH(AK10,{"Baja";"Media";"Alta"},0),1,2,3), CHOOSE(MATCH(AM10,{"Baja";"Media";"Alta"},0),1,2,3)),0) -> 12 | AO10: =IF(AN10=0,"Pendiente",IF(AN10<=15,"Bajo",IF(AN10<=21,"Medio","Alto"))) -> Bajo | AR10: =VLOOKUP(A10,#REF!,2,FALSE) -> #REF! | AS10: https://app.icepanel.io/landscapes/w71QNHgfDvF79GrSuA3r/versions/latest/diagrams/editor?diagram=qXCLgnJ6TO&model=z8l3of38d7&overlay_tab=tags&x1=-642.7&y1=-192&x2=1666.7&y2=832 | AT10: https://dev.azure.com/BancoPichinchaEC/adi-especificaciones-tecnicas/_git/adi-doc-tecspec-tribu-integracion-apis?path=/sp%20-%20Soporte/tnd-msa-sp-orqclientes0019 | AU10: https://dev.azure.com/BancoPichinchaEC/tpl-bus-omnicanal/_git/sqb-msa-orqclientes0019 | AV10: 1 | AW10: https://pichincha.atlassian.net/browse/PCBG-589
A11: ORQClientes0022 | B11: =CONCATENATE(LOWER(E11),"-msa-sp-",LOWER(A11)) -> tnd-msa-sp-orqclientes0022 | C11: Consulta información de cliente con agencia virtual | D11: TRIBU SEGMENTOS Y NEGOCIOS DIGITALES | E11: =VLOOKUP(D11,Tribus!$A$1:$B$33,2,FALSE) -> tnd | F11: Bus Omnicanalidad | G11: ORQ | H11: Completado | I11: A Desarrollo | J11: WSClientes0046 --> ConsultarClienteVirtual01 | K11: Bus Omnicanalidad | L11: ON-PREMISE | M11: 1 | N11: Baja | O11: SOAP | P11: 1 | Q11: Baja | R11: Ninguna | S11: 0 | T11: Baja | U11: Ninguna | W11: Baja | X11: 49.4k | Y11: 163ms | AB11: Baja | AC11: Si puede ser probado por las app | AD11: Baja | AE11: AREA MICROFINANZAS | AF11: APIGee - cia-api-sp-ape-virtual-customers | AG11: Segun BDD: 00650 - Microfinanzas | AH11: 1 | AI11: Baja | AJ11: Ninguno | AK11: Baja | AL11: ConsultarInformacionClienteVirtual01 | AM11: Baja | AN11: =IFERROR(SUM(CHOOSE(MATCH(N11,{"Baja";"Media";"Alta"},0),1,2,3), CHOOSE(MATCH(Q11,{"Baja";"Media";"Alta"},0),1,2,3), CHOOSE(MATCH(T11,{"Baja";"Media";"Alta"},0),1,2,3), CHOOSE(MATCH(W11,{"Baja";"Media";"Alta"},0),1,2,3), CHOOSE(MATCH(AB11,{"Baja";"Media";"Alta"},0),1,2,3), CHOOSE(MATCH(AD11,{"Baja";"Media";"Alta"},0),1,2,3), CHOOSE(MATCH(AI11,{"Baja";"Media";"Alta"},0),1,2,3), CHOOSE(MATCH(AK11,{"Baja";"Media";"Alta"},0),1,2,3), CHOOSE(MATCH(AM11,{"Baja";"Media";"Alta"},0),1,2,3)),0) -> 9 | AO11: =IF(AN11=0,"Pendiente",IF(AN11<=15,"Bajo",IF(AN11<=21,"Medio","Alto"))) -> Bajo | AR11: =VLOOKUP(A11,#REF!,2,FALSE) -> #REF! | AS11: https://s.icepanel.io/wJSECZOwwNkkW8/oy6e | AT11: https://dev.azure.com/BancoPichinchaEC/adi-especificaciones-tecnicas/_git/adi-doc-tecspec-tribu-integracion-apis?path=/sp%20-%20Soporte/tnd-msa-sp-orqclientes0022 | AU11: sqb-msa-orqclientes0022 - Repos | AV11: 1 | AW11: https://pichincha.atlassian.net/browse/PCBG-590
A12: ORQClientes0023 | B12: =CONCATENATE(LOWER(E12),"-msa-sp-",LOWER(A12)) -> tpr-msa-sp-orqclientes0023 | C12: Consultar Creditos y Garantia | D12: TRIBU PRODUCTOS | E12: =VLOOKUP(D12,Tribus!$A$1:$B$33,2,FALSE) -> tpr | F12: Bus Omnicanalidad | G12: ORQ | H12: Completado | I12: A Desarrollo | J12: WSClientes0024 WSClientes0078 WSClientes0090 WSClientes0091 | K12: Bus Omnicanalidad Was Omnicanalidad | L12: ON-PREMISE | M12: 4 | N12: Alta | O12: 8511 - SOAP | P12: 1 | Q12: Baja | R12: Ninguna | S12: 0 | T12: Baja | U12: Ninguna | W12: Baja | X12: 896 | Y12: 375ms | AB12: Baja | AC12: Si puede ser probado por las app | AD12: Baja | AE12: COE_TRANSFORMACION_PROCESOS | AG12: Default Web Site:443,8043 (/BPMPichincha) Default Web Site:443,8043 (/BPMPichinchaCH) Default Web Site:443,8043 (/BPMPichinchaCP) Default Web Site:443,8043 (/BPMPichinchaAS) | AH12: 3 | AI12: Media | AJ12: Ninguno | AK12: Baja | AL12: ConsultarCreditosGarantia | AM12: Baja | AN12: =IFERROR(SUM(CHOOSE(MATCH(N12,{"Baja";"Media";"Alta"},0),1,2,3), CHOOSE(MATCH(Q12,{"Baja";"Media";"Alta"},0),1,2,3), CHOOSE(MATCH(T12,{"Baja";"Media";"Alta"},0),1,2,3), CHOOSE(MATCH(W12,{"Baja";"Media";"Alta"},0),1,2,3), CHOOSE(MATCH(AB12,{"Baja";"Media";"Alta"},0),1,2,3), CHOOSE(MATCH(AD12,{"Baja";"Media";"Alta"},0),1,2,3), CHOOSE(MATCH(AI12,{"Baja";"Media";"Alta"},0),1,2,3), CHOOSE(MATCH(AK12,{"Baja";"Media";"Alta"},0),1,2,3), CHOOSE(MATCH(AM12,{"Baja";"Media";"Alta"},0),1,2,3)),0) -> 12 | AO12: =IF(AN12=0,"Pendiente",IF(AN12<=15,"Bajo",IF(AN12<=21,"Medio","Alto"))) -> Bajo | AQ12: Considerar que consume el WSClientes0090 que no estuvo contemplado en la ola 1 | AR12: =VLOOKUP(A12,#REF!,2,FALSE) -> #REF! | AS12: https://s.icepanel.io/wJSECZOwwNkkW8/CUjN | AT12: https://dev.azure.com/BancoPichinchaEC/adi-especificaciones-tecnicas/_git/adi-doc-tecspec-tribu-integracion-apis?version=GBmaster&path=/sp%20-%20Soporte/tpr-msa-sp-orqclientes0023 | AU12: https://dev.azure.com/BancoPichinchaEC/tpl-bus-omnicanal/_git/sqb-msa-orqclientes0023 | AV12: 1 | AW12: https://pichincha.atlassian.net/browse/PCBG-591
A13: ORQClientes0024 | B13: =CONCATENATE(LOWER(E13),"-msa-sp-",LOWER(A13)) -> tpr-msa-sp-orqclientes0024 | C13: Consultar Cuentas e Inversiones del Cliente | D13: TRIBU PRODUCTOS | E13: =VLOOKUP(D13,Tribus!$A$1:$B$33,2,FALSE) -> tpr | F13: Bus Omnicanalidad | G13: ORQ | H13: Completado | I13: A Desarrollo | J13: WSClientes0075 -> ConsultarSaldosCuenta01 WSClientes0081 -> ConsultarCuentasFirmaAutorizada01 WSClientes0082 -> ConsultarCuentasTipoEstado01 WSProductos0016 -> ConsultarCotitularesCuenta02 | K13: Bus Omnicanalidad | L13: ON-PREMISE | M13: 4 | N13: Alta | O13: 8937 - REST 8511 - SOAP | P13: 2 | Q13: Media | R13: Ninguna | S13: 0 | T13: Baja | U13: Ninguna | W13: Baja | X13: 10.26K | Y13: 227ms | AB13: Baja | AC13: Si puede ser probado por las app | AD13: Baja | AE13: COE_TRANSFORMACION_PROCESOS | AF13: 0 | AG13: Default Web Site:443,8043 (/BPMPichincha) Default Web Site:443,8043 (/BPMPichinchaCH) Default Web Site:443,8043 (/BPMPichinchaCP) Segun BDD: Bizagi: 00657 | AH13: 4 | AI13: Alta | AJ13: ninguno | AK13: Baja | AL13: ConsultarCuentasInversionesCliente01 | AM13: Baja | AN13: =IFERROR(SUM(CHOOSE(MATCH(N13,{"Baja";"Media";"Alta"},0),1,2,3), CHOOSE(MATCH(Q13,{"Baja";"Media";"Alta"},0),1,2,3), CHOOSE(MATCH(T13,{"Baja";"Media";"Alta"},0),1,2,3), CHOOSE(MATCH(W13,{"Baja";"Media";"Alta"},0),1,2,3), CHOOSE(MATCH(AB13,{"Baja";"Media";"Alta"},0),1,2,3), CHOOSE(MATCH(AD13,{"Baja";"Media";"Alta"},0),1,2,3), CHOOSE(MATCH(AI13,{"Baja";"Media";"Alta"},0),1,2,3), CHOOSE(MATCH(AK13,{"Baja";"Media";"Alta"},0),1,2,3), CHOOSE(MATCH(AM13,{"Baja";"Media";"Alta"},0),1,2,3)),0) -> 14 | AO13: =IF(AN13=0,"Pendiente",IF(AN13<=15,"Bajo",IF(AN13<=21,"Medio","Alto"))) -> Bajo | AR13: =VLOOKUP(A13,#REF!,2,FALSE) -> #REF! | AS13: https://s.icepanel.io/wJSECZOwwNkkW8/kzAK | AT13: https://dev.azure.com/BancoPichinchaEC/adi-especificaciones-tecnicas/_git/adi-doc-tecspec-tribu-integracion-apis?path=/sp%20-%20Soporte/tpr-msa-sp-orqclientes0024 | AU13: https://dev.azure.com/BancoPichinchaEC/tpl-bus-omnicanal/_git/sqb-msa-orqclientes0024 | AV13: 1 | AW13: https://pichincha.atlassian.net/browse/PCBG-592
A14: ORQClientes0025 | B14: =CONCATENATE(LOWER(E14),"-msa-sp-",LOWER(A14)) -> tpr-msa-sp-orqclientes0025 | C14: Consultar Cheques Protestados del Cliente | D14: TRIBU PRODUCTOS | E14: =VLOOKUP(D14,Tribus!$A$1:$B$33,2,FALSE) -> tpr | F14: Bus Omnicanalidad | G14: ORQ | H14: Completado | I14: A Desarrollo | J14: ORQClientes0025 WSClientes0001 (ConsultarCuentasActivas01) -> UMPProductos0049 (ConsultarPosicionConsolidadaCliente01) -> TX060450 UMPProductos0001 (ConsultarCuentas01) -> TX060453 / 060452 UMPProductos0066 (ConsultarFirmaUnicaIndependiente01) -> TX064014 WSClientes0082 (ConsultarCuentasTipoEstado01) -> UMPProductos0021 (ConsultarCuentas21) -> Consulta de Cuentas del cliente en Bancs TX060453 -> TX060452 -> TX de consulta cuentas en Bancs WSClientes0025 (ConsultarInformacionChequeProtestado01) -> UMPClientes0010 (ConsultarInformacionChequeProtestado01)-> TX051059 | K14: Bus Omnicanalidad | L14: ON-PREMISE | M14: 3 | N14: Media | O14: 8511 - SOAP | Q14: Baja | R14: Ninguna | S14: 0 | T14: Baja | U14: Ninguna | W14: Baja | X14: 13.3K | Y14: 530 ms | AB14: Baja | AC14: Si puede ser probado por las app | AD14: Baja | AE14: COE_TRANSFORMACION_PROCESOS TRIBU ADMINISTRACION DE CREDITO | AF14: deployment-fda-msa-dm-orqclientes*-*; ORQClientes0067.API | AG14: Default Web Site:443,8043 (/BPMPichincha) Default Web Site:443,8043 (/BPMPichinchaCH) Default Web Site:443,8043 (/BPMPichinchaCP) | AI14: Baja | AJ14: Ninguno | AK14: Baja | AL14: ConsultarChequesProtestadosCliente01 | AM14: Baja | AN14: =IFERROR(SUM(CHOOSE(MATCH(N14,{"Baja";"Media";"Alta"},0),1,2,3), CHOOSE(MATCH(Q14,{"Baja";"Media";"Alta"},0),1,2,3), CHOOSE(MATCH(T14,{"Baja";"Media";"Alta"},0),1,2,3), CHOOSE(MATCH(W14,{"Baja";"Media";"Alta"},0),1,2,3), CHOOSE(MATCH(AB14,{"Baja";"Media";"Alta"},0),1,2,3), CHOOSE(MATCH(AD14,{"Baja";"Media";"Alta"},0),1,2,3), CHOOSE(MATCH(AI14,{"Baja";"Media";"Alta"},0),1,2,3), CHOOSE(MATCH(AK14,{"Baja";"Media";"Alta"},0),1,2,3), CHOOSE(MATCH(AM14,{"Baja";"Media";"Alta"},0),1,2,3)),0) -> 10 | AO14: =IF(AN14=0,"Pendiente",IF(AN14<=15,"Bajo",IF(AN14<=21,"Medio","Alto"))) -> Bajo | AR14: =VLOOKUP(A14,#REF!,2,FALSE) -> #REF! | AS14: https://app.icepanel.io/landscapes/w71QNHgfDvF79GrSuA3r/versions/latest/diagrams/editor?diagram=5SlzCdmf2o&model=052757cjuefp&overlay_tab=tags&x1=-301.6&y1=-192&x2=1697.6&y2=832 | AT14: https://dev.azure.com/BancoPichinchaEC/adi-especificaciones-tecnicas/_git/adi-doc-tecspec-tribu-integracion-apis?path=/sp%20-%20Soporte/tpr-msa-sp-orqclientes0025 | AU14: https://dev.azure.com/BancoPichinchaEC/tpl-bus-omnicanal/_git/sqb-msa-orqclientes0025 | AV14: 1 | AW14: https://pichincha.atlassian.net/browse/PCBG-593
A15: ORQClientes0026 | B15: =CONCATENATE(LOWER(E15),"-msa-sp-",LOWER(A15)) -> tpr-msa-sp-orqclientes0026 | C15: Consulta de Creditos, Debitos y Cuentas Activas del Cliente | D15: TRIBU PRODUCTOS | E15: =VLOOKUP(D15,Tribus!$A$1:$B$33,2,FALSE) -> tpr | F15: Bus Omnicanalidad | G15: ORQ | H15: Completado | I15: A Desarrollo | J15: WSClientes0082 WSProductos0130 | K15: Bus Omnicanalidad | L15: ON-PREMISE | M15: 2 | N15: Media | O15: SOAP 8511 - SOAP | P15: 1 | Q15: Baja | R15: Ninguna | S15: 0 | T15: Baja | U15: Ninguna | W15: Baja | X15: 516 | Y15: 559ms | AB15: Baja | AC15: Si puede ser probado por las app | AD15: Baja | AE15: COE_TRANSFORMACION_PROCESOS | AG15: Default Web Site:443,8043 (/BPMPichincha) Default Web Site:443,8043 (/BPMPichinchaCH) Default Web Site:443,8043 (/BPMPichinchaCP) | AH15: 3 | AI15: Media | AJ15: Ninguno | AK15: Baja | AL15: ConsultaCreditosDebitosCuentasActivasCliente01 | AM15: Baja | AN15: =IFERROR(SUM(CHOOSE(MATCH(N15,{"Baja";"Media";"Alta"},0),1,2,3), CHOOSE(MATCH(Q15,{"Baja";"Media";"Alta"},0),1,2,3), CHOOSE(MATCH(T15,{"Baja";"Media";"Alta"},0),1,2,3), CHOOSE(MATCH(W15,{"Baja";"Media";"Alta"},0),1,2,3), CHOOSE(MATCH(AB15,{"Baja";"Media";"Alta"},0),1,2,3), CHOOSE(MATCH(AD15,{"Baja";"Media";"Alta"},0),1,2,3), CHOOSE(MATCH(AI15,{"Baja";"Media";"Alta"},0),1,2,3), CHOOSE(MATCH(AK15,{"Baja";"Media";"Alta"},0),1,2,3), CHOOSE(MATCH(AM15,{"Baja";"Media";"Alta"},0),1,2,3)),0) -> 11 | AO15: =IF(AN15=0,"Pendiente",IF(AN15<=15,"Bajo",IF(AN15<=21,"Medio","Alto"))) -> Bajo | AR15: =VLOOKUP(A15,#REF!,2,FALSE) -> #REF! | AS15: https://s.icepanel.io/wJSECZOwwNkkW8/r3I4 | AT15: https://dev.azure.com/BancoPichinchaEC/adi-especificaciones-tecnicas/_git/adi-doc-tecspec-tribu-integracion-apis?path=/sp%20-%20Soporte/tpr-msa-sp-orqclientes0026 | AU15: https://dev.azure.com/BancoPichinchaEC/tpl-bus-omnicanal/_git/sqb-msa-orqclientes0026 | AV15: 1 | AW15: https://pichincha.atlassian.net/browse/PCBG-594
A16: ORQClientes0027 | B16: =CONCATENATE(LOWER(E16),"-msa-sp-",LOWER(A16)) -> tmp-msa-sp-orqclientes0027 | C16: Consulta tarjetas de Credito BP | D16: TRIBU MEDIOS DE PAGO | E16: =VLOOKUP(D16,Tribus!$A$1:$B$33,2,FALSE) -> tmp | F16: Bus Omnicanalidad | G16: ORQ | H16: Completado | I16: A Desarrollo | J16: WSClientes0023 -> ConsultarTarjetasCreditoBP01 WSClientes0076 -> ConsultarDiasMoraTarjeta01 | K16: Bus Omnicanalidad | L16: ON-PREMISE | M16: 1 | N16: Baja | O16: 8511 - SOAP | P16: 1 | Q16: Baja | R16: Ninguna | S16: 0 | T16: Baja | U16: Ninguna | W16: Baja | X16: 862 | Y16: 99.3ms | AB16: Baja | AC16: Si puede ser probado por las app | AD16: Baja | AE16: COE_TRANSFORMACION_PROCESOS | AF16: Ninguno | AG16: Default Web Site:443,8043 (/BPMPichincha) Default Web Site:443,8043 (/BPMPichinchaCH) Default Web Site:443,8043 (/BPMPichinchaCP) | AH16: 3 | AI16: Media | AJ16: Ninguno | AK16: Baja | AL16: ConsultarTarjetasCreditoBP01 | AM16: Baja | AN16: =IFERROR(SUM(CHOOSE(MATCH(N16,{"Baja";"Media";"Alta"},0),1,2,3), CHOOSE(MATCH(Q16,{"Baja";"Media";"Alta"},0),1,2,3), CHOOSE(MATCH(T16,{"Baja";"Media";"Alta"},0),1,2,3), CHOOSE(MATCH(W16,{"Baja";"Media";"Alta"},0),1,2,3), CHOOSE(MATCH(AB16,{"Baja";"Media";"Alta"},0),1,2,3), CHOOSE(MATCH(AD16,{"Baja";"Media";"Alta"},0),1,2,3), CHOOSE(MATCH(AI16,{"Baja";"Media";"Alta"},0),1,2,3), CHOOSE(MATCH(AK16,{"Baja";"Media";"Alta"},0),1,2,3), CHOOSE(MATCH(AM16,{"Baja";"Media";"Alta"},0),1,2,3)),0) -> 10 | AO16: =IF(AN16=0,"Pendiente",IF(AN16<=15,"Bajo",IF(AN16<=21,"Medio","Alto"))) -> Bajo | AR16: =VLOOKUP(A16,#REF!,2,FALSE) -> #REF! | AS16: https://app.icepanel.io/landscapes/w71QNHgfDvF79GrSuA3r/versions/latest/diagrams/editor?diagram=xs1LYUUDwU&model=g103dyijmna&overlay_tab=tags&x1=-642.7&y1=-192&x2=1666.7&y2=832 | AT16: https://dev.azure.com/BancoPichinchaEC/adi-especificaciones-tecnicas/_git/adi-doc-tecspec-tribu-integracion-apis?version=GBmaster&path=/sp%20-%20Soporte/tmp-msa-sp-orqclientes0027 | AU16: https://dev.azure.com/BancoPichinchaEC/tpl-bus-omnicanal/_git/sqb-msa-orqclientes0027 | AV16: 1 | AW16: https://pichincha.atlassian.net/browse/PCBG-595
A17: ORQClientes0028 | B17: =CONCATENATE(LOWER(E17),"-msa-sp-",LOWER(A17)) -> tnd-msa-sp-orqclientes0028 | C17: Cancelar Actualizacion de Datos Delay | D17: TRIBU SEGMENTOS Y NEGOCIOS DIGITALES | E17: =VLOOKUP(D17,Tribus!$A$1:$B$33,2,FALSE) -> tnd | F17: Bus Omnicanalidad | G17: ORQ | H17: Completado | I17: A Desarrollo | J17: WSTecnicos0035 WSTecnicos0036 CE_EVENTOS | K17: Was Omnicanalidad | L17: ON-PREMISE | M17: 2 | N17: Media | O17: Rest desde datapower externo Soap - propio del servicio | P17: 2 | Q17: Media | R17: 0 | S17: 0 | T17: Baja | U17: Ninguna | W17: Baja | X17: 4 | Y17: 68ms | AB17: Baja | AC17: Si puede ser probado por las app | AD17: Baja | AE17: COE_TRANSFORMACION_PROCESOS TRIBU SEGMENTOS Y NEGOCIOS DIGITALES | AF17: datapower externo - WSAP117401007 | AG17: Bizagi Segun BDD: 00344 - CRM Gestión Comercial (Salesforce) | AH17: 2 | AI17: Media | AJ17: Ninguno | AK17: Baja | AL17: CancelarActualizacionDatosDelay31 | AM17: Baja | AN17: =IFERROR(SUM(CHOOSE(MATCH(N17,{"Baja";"Media";"Alta"},0),1,2,3), CHOOSE(MATCH(Q17,{"Baja";"Media";"Alta"},0),1,2,3), CHOOSE(MATCH(T17,{"Baja";"Media";"Alta"},0),1,2,3), CHOOSE(MATCH(W17,{"Baja";"Media";"Alta"},0),1,2,3), CHOOSE(MATCH(AB17,{"Baja";"Media";"Alta"},0),1,2,3), CHOOSE(MATCH(AD17,{"Baja";"Media";"Alta"},0),1,2,3), CHOOSE(MATCH(AI17,{"Baja";"Media";"Alta"},0),1,2,3), CHOOSE(MATCH(AK17,{"Baja";"Media";"Alta"},0),1,2,3), CHOOSE(MATCH(AM17,{"Baja";"Media";"Alta"},0),1,2,3)),0) -> 12 | AO17: =IF(AN17=0,"Pendiente",IF(AN17<=15,"Bajo",IF(AN17<=21,"Medio","Alto"))) -> Bajo | AQ17: RITM0738122 / RITM0745618 | AR17: =VLOOKUP(A17,#REF!,2,FALSE) -> #REF! | AS17: https://s.icepanel.io/wJSECZOwwNkkW8/sDBV | AT17: https://dev.azure.com/BancoPichinchaEC/adi-especificaciones-tecnicas/_git/adi-doc-tecspec-tribu-integracion-apis?version=GBmaster&path=/sp%20-%20Soporte/tnd-msa-sp-orqclientes0028 | AU17: https://dev.azure.com/BancoPichinchaEC/tpl-bus-omnicanal/_git/sqb-msa-orqclientes0028 | AV17: 1 | AW17: https://pichincha.atlassian.net/browse/PCBG-596
A18: ORQClientes0029 | B18: =CONCATENATE(LOWER(E18),"-msa-sp-",LOWER(A18)) -> tnd-msa-sp-orqclientes0029 | C18: Consulta datos basicos del Cliente | D18: TRIBU SEGMENTOS Y NEGOCIOS DIGITALES | E18: =VLOOKUP(D18,Tribus!$A$1:$B$33,2,FALSE) -> tnd | F18: Bus Omnicanalidad | G18: ORQ | H18: Completado | I18: A Desarrollo | J18: WSClientes0024 → ConsultarIdentificacion01 (destino: IIB) WSClientes0077 → ConsultarDatoBasicoCliente01 (destino: IIB) WSClientes0078 → consultarClienteSAR01 (destino: IIB) WSClientes0011 → ConsultarDatosIdentificacionCliente01 (destino: IIB) WSClientes0012 → ConsultarDatoDemograficoCliente01 (destino: IIB) WSClientes0013 → ConsultarDatosLocalizacionCliente01 (destino: IIB) WSClientes0007 → ConsultarContactoTransaccional01 (destino: IIB) | K18: Bus Omnicanalidad | L18: ON-PREMISE | M18: 7 | N18: Alta | O18: SOAP 8511 - SOAP | P18: 1 | Q18: Baja | R18: NO | S18: 0 | T18: Baja | U18: Ninguna | W18: Baja | X18: 1164 | Y18: 890ms | AB18: Baja | AC18: Si puede ser probado por las app | AD18: Baja | AE18: COE_TRANSFORMACION_PROCESOS | AG18: Default Web Site:443,8043 (/BPMPichincha) Default Web Site:443,8043 (/BPMPichinchaCH) Default Web Site:443,8043 (/BPMPichinchaCP) Default Web Site:443,8043 (/BPMPichinchaAS) | AH18: 4 | AI18: Media | AJ18: NO | AK18: Baja | AL18: ConsultarDatosCliente01 | AM18: Baja | AN18: =IFERROR(SUM(CHOOSE(MATCH(N18,{"Baja";"Media";"Alta"},0),1,2,3), CHOOSE(MATCH(Q18,{"Baja";"Media";"Alta"},0),1,2,3), CHOOSE(MATCH(T18,{"Baja";"Media";"Alta"},0),1,2,3), CHOOSE(MATCH(W18,{"Baja";"Media";"Alta"},0),1,2,3), CHOOSE(MATCH(AB18,{"Baja";"Media";"Alta"},0),1,2,3), CHOOSE(MATCH(AD18,{"Baja";"Media";"Alta"},0),1,2,3), CHOOSE(MATCH(AI18,{"Baja";"Media";"Alta"},0),1,2,3), CHOOSE(MATCH(AK18,{"Baja";"Media";"Alta"},0),1,2,3), CHOOSE(MATCH(AM18,{"Baja";"Media";"Alta"},0),1,2,3)),0) -> 12 | AO18: =IF(AN18=0,"Pendiente",IF(AN18<=15,"Bajo",IF(AN18<=21,"Medio","Alto"))) -> Bajo | AR18: =VLOOKUP(A18,#REF!,2,FALSE) -> #REF! | AS18: https://s.icepanel.io/wJSECZOwwNkkW8/sZlg | AT18: https://dev.azure.com/BancoPichinchaEC/adi-especificaciones-tecnicas/_git/adi-doc-tecspec-tribu-integracion-apis?version=GBmaster&path=/sp%20-%20Soporte/tnd-msa-sp-orqclientes0029 | AU18: https://dev.azure.com/BancoPichinchaEC/tpl-bus-omnicanal/_git/sqb-msa-orqclientes0029 | AV18: 1 | AW18: https://pichincha.atlassian.net/browse/PCBG-597
A19: ORQClientes0035 | B19: =CONCATENATE(LOWER(E19),"-msa-sp-",LOWER(A19)) -> tnd-msa-sp-orqclientes0035 | C19: Orquestar los web service para creacion del cliente | D19: TRIBU SEGMENTOS Y NEGOCIOS DIGITALES | E19: =VLOOKUP(D19,Tribus!$A$1:$B$33,2,FALSE) -> tnd | F19: Bus Omnicanalidad | G19: ORQ | H19: Completado | I19: A Desarrollo | J19: WSClientes0024 -< ConsultarIdentificacion01 WSClientes0038 -> OperacionEconomicosCliente52 WSClientes0055 -> OperacionActividadEconomicaCliente51 WSClientes0060 -> OperacionDatosComplementariosCliente51 (opc1/ops2/opc3) WSClientes0061-> OperacionDemograficosCliente51 WSClientes0062 -> OperacionIdentificacionCliente51 WSClientes0063 -> OperacionReferenciasCliente51 WSClientes0096 -> CrearProspecto21 WSClientes0098 -> transmisionClienteSFI01 WSClientes0099 -> OperacionLocalizacion51 WSClientes0101 -> OperacionRelacionesCliente51 WSClientes0102 -> SegmentacionEntradaFija01 WSTecnicos0076 -> crearLogModificaciones21 WSTecnicos0063 -> obtenerCatalogosSigloBancs01 | K19: Bus Omnicanalidad Was Omnicanalidad | L19: ON-PREMISE | M19: 14 | N19: Alta | O19: REST - datapowerexterno SOAP | P19: 2 | Q19: Media | R19: Ninguna | S19: 0 | T19: Baja | U19: Catalogo de sector economico, consume WSTecnicos0063 | V19: WSTecnicos0063 | W19: Media | X19: 64 | Y19: 2.26s | AB19: Baja | AC19: Si puede ser probado por las app | AD19: Baja | AE19: TRIBU CANALES TRIBU PRODUCTOS AREA MICROFINANZAS | AF19: 0 | AG19: Servicios_Consumidos_Vinculacion_Integral Segun BDD: 00650 - Microfinanzas Movilidad app movil 00662 - Referidos | AH19: 3 | AI19: Media | AJ19: ninguno | AK19: Baja | AL19: CreacionCliente21 | AM19: Baja | AN19: =IFERROR(SUM(CHOOSE(MATCH(N19,{"Baja";"Media";"Alta"},0),1,2,3), CHOOSE(MATCH(Q19,{"Baja";"Media";"Alta"},0),1,2,3), CHOOSE(MATCH(T19,{"Baja";"Media";"Alta"},0),1,2,3), CHOOSE(MATCH(W19,{"Baja";"Media";"Alta"},0),1,2,3), CHOOSE(MATCH(AB19,{"Baja";"Media";"Alta"},0),1,2,3), CHOOSE(MATCH(AD19,{"Baja";"Media";"Alta"},0),1,2,3), CHOOSE(MATCH(AI19,{"Baja";"Media";"Alta"},0),1,2,3), CHOOSE(MATCH(AK19,{"Baja";"Media";"Alta"},0),1,2,3), CHOOSE(MATCH(AM19,{"Baja";"Media";"Alta"},0),1,2,3)),0) -> 14 | AO19: =IF(AN19=0,"Pendiente",IF(AN19<=15,"Bajo",IF(AN19<=21,"Medio","Alto"))) -> Bajo | AR19: =VLOOKUP(A19,#REF!,2,FALSE) -> #REF! | AS19: https://s.icepanel.io/wJSECZOwwNkkW8/NQF9 | AT19: https://dev.azure.com/BancoPichinchaEC/adi-especificaciones-tecnicas/_git/adi-doc-tecspec-tribu-integracion-apis?version=GBmaster&path=/sp%20-%20Soporte/tnd-msa-sp-orqclientes0035 | AU19: https://dev.azure.com/BancoPichinchaEC/tpl-bus-omnicanal/_git/sqb-msa-orqclientes0035 | AV19: 1 | AW19: https://pichincha.atlassian.net/browse/PCBG-598
A20: ORQClientes0036 | B20: =CONCATENATE(LOWER(E20),"-msa-sp-",LOWER(A20)) -> tnd-msa-sp-orqclientes0036 | C20: Consumir la WS para actualizacion del cliente | D20: TRIBU SEGMENTOS Y NEGOCIOS DIGITALES | E20: =VLOOKUP(D20,Tribus!$A$1:$B$33,2,FALSE) -> tnd | F20: Bus Omnicanalidad | G20: ORQ | H20: Completado | I20: A Desarrollo | J20: ORQClientes0036 WSClientes0061 (OperacionDemograficosCliente51) -> UMPClientes0077 (OperacionDemograficosCliente51) -> TX061406 WSClientes0103 (ActualizarInformacionCliente31) -> umpclientes0102 (Actualizacion del cliente en bancs) -> TX067510 (Procedimiento que realiza la operacion de actualizacion del cliente) WSClientes0098 (transmisionClienteSFI01) -> UMPClientes0100 (TransmisionClienteSFI) -> BDD: CREDIFE, SP: CFE_TRANSMISIONCLIENTESS1_MVL WSTecnicos0063 (obtenerCatalogosSigloBancs01) -> umptecnicos0066 (Consulta de catalogos a BANCS , CREDIFE y S21) -> jndi.sfi p11431BDD CREDIFE, jndi.catalogo.bancs p1521 BDD p012band_taf, jndi.catalogo.sigloBDD SRVPPRD WSClientes0038 (ConsultarDetalleAdicionalesCliente01) -> UMPClientes0020 (ConsultaInformacionCliente01) -> TX067050 (opc 1, 5, 15, 21) UMPClientes0061 (ActualizarInfAdicionalCliente31) -> TX067118 UMPClientes0057 (ActualizarInformacionCliente31) -> TX067116 WSClientes0101 (OperacionRelacionesCliente51) -> UMPClientes0076 (OperacionInformacionComplementariaRelaciones51) -> TX067151 (Consultar informacion complementaria de referencia del cliente) WSTecnicos0076 (crearLogModificaciones21) -> umptecnicos0098 (CrearLogModificacionesDao) -> Esquema: portal -> jndi.bancs.clientes | K20: Bus Omnicanalidad Was Omnicanalidad | L20: ON-PREMISE | M20: 6 | N20: Alta | O20: REST SOAP | P20: 2 | Q20: Media | R20: Ninguna | S20: 0 | T20: Baja | U20: Almacena información de backend en cache, consume WSTecnicos0063 | V20: WSTecnicos0063 | W20: Media | X20: 2.84K | Y20: 1.34s | AB20: Baja | AC20: Si puede ser probado por las app | AD20: Baja | AE20: AREA MICROFINANZAS TRIBU CANALES | AF20: Ninguno | AG20: Servicios_Consumidos_Vinculacion_Integral Segun BDD: 00650 - Microfinanzas Movilidad app movil 00662 - Referidos | AH20: 3 | AI20: Baja | AJ20: Ninguno | AK20: Baja | AL20: ActualizacionCliente31 | AM20: Baja | AN20: =IFERROR(SUM(CHOOSE(MATCH(N20,{"Baja";"Media";"Alta"},0),1,2,3), CHOOSE(MATCH(Q20,{"Baja";"Media";"Alta"},0),1,2,3), CHOOSE(MATCH(T20,{"Baja";"Media";"Alta"},0),1,2,3), CHOOSE(MATCH(W20,{"Baja";"Media";"Alta"},0),1,2,3), CHOOSE(MATCH(AB20,{"Baja";"Media";"Alta"},0),1,2,3), CHOOSE(MATCH(AD20,{"Baja";"Media";"Alta"},0),1,2,3), CHOOSE(MATCH(AI20,{"Baja";"Media";"Alta"},0),1,2,3), CHOOSE(MATCH(AK20,{"Baja";"Media";"Alta"},0),1,2,3), CHOOSE(MATCH(AM20,{"Baja";"Media";"Alta"},0),1,2,3)),0) -> 13 | AO20: =IF(AN20=0,"Pendiente",IF(AN20<=15,"Bajo",IF(AN20<=21,"Medio","Alto"))) -> Bajo | AR20: =VLOOKUP(A20,#REF!,2,FALSE) -> #REF! | AS20: https://app.icepanel.io/landscapes/w71QNHgfDvF79GrSuA3r/versions/latest/diagrams/editor?diagram=0xsCJ6T9F7&model=9JNMa0g1gL&overlay_tab=tags&x1=-301.6&y1=-192&x2=1697.6&y2=832 | AT20: https://dev.azure.com/BancoPichinchaEC/adi-especificaciones-tecnicas/_git/adi-doc-tecspec-tribu-integracion-apis?version=GBmaster&path=/sp%20-%20Soporte/tnd-msa-sp-orqclientes0036 | AU20: https://dev.azure.com/BancoPichinchaEC/tpl-bus-omnicanal/_git/sqb-msa-orqclientes0036 | AV20: 1 | AW20: https://pichincha.atlassian.net/browse/PCBG-599
A21: ORQClientes0037 | B21: =CONCATENATE(LOWER(E21),"-msa-sp-",LOWER(A21)) -> tnd-msa-sp-orqclientes0037 | C21: Consulta las preferencias de notificaciones de un cliente cuando crea el usuario por banca web. | D21: TRIBU SEGMENTOS Y NEGOCIOS DIGITALES | E21: =VLOOKUP(D21,Tribus!$A$1:$B$33,2,FALSE) -> tnd | F21: Bus Omnicanalidad | G21: ORQ | H21: Completado | I21: A Desarrollo | J21: WSClientes0006(ConsultarInformacionBasica01) WSClientes0007(ConsultarContactoTransaccional0) WSClientes0010(consultarGrupoClaveDigital01) WSClientes0024(ConsultarIdentificacion01) WSClientes0026(consultar02) → srvppomnica WSClientes0030(ConsultarContactoNotificacion01) WSTecnicos0039(consultarNotificacion01) → srvppomnica WSSeguridad0067(consultarDispositivosDetectId01) CE_EVENTOS | K21: BUS OMNICANAL WAS OMNICANAL | L21: ON-PREMISE | M21: 2 | N21: Media | O21: SOAP | P21: 1 | Q21: Baja | R21: Ninguna | S21: 0 | T21: Baja | U21: Ninguna | V21: No aplica | W21: Baja | X21: 3.03k | Y21: 373 ms | AB21: Baja | AC21: Si puede ser probado por las app | AD21: Baja | AE21: TRIBU CANALES | AF21: CANALES | AG21: NO aplica | AH21: 1 | AI21: Baja | AJ21: 0 | AK21: Baja | AL21: ConsultarPreferenciaNotificacionCliente01 | AM21: Baja | AN21: =IFERROR(SUM(CHOOSE(MATCH(N21,{"Baja";"Media";"Alta"},0),1,2,3), CHOOSE(MATCH(Q21,{"Baja";"Media";"Alta"},0),1,2,3), CHOOSE(MATCH(T21,{"Baja";"Media";"Alta"},0),1,2,3), CHOOSE(MATCH(W21,{"Baja";"Media";"Alta"},0),1,2,3), CHOOSE(MATCH(AB21,{"Baja";"Media";"Alta"},0),1,2,3), CHOOSE(MATCH(AD21,{"Baja";"Media";"Alta"},0),1,2,3), CHOOSE(MATCH(AI21,{"Baja";"Media";"Alta"},0),1,2,3), CHOOSE(MATCH(AK21,{"Baja";"Media";"Alta"},0),1,2,3), CHOOSE(MATCH(AM21,{"Baja";"Media";"Alta"},0),1,2,3)),0) -> 10 | AO21: =IF(AN21=0,"Pendiente",IF(AN21<=15,"Bajo",IF(AN21<=21,"Medio","Alto"))) -> Bajo | AR21: =VLOOKUP(A21,#REF!,2,FALSE) -> #REF! | AS21: ORQClientes0037 Component Diagram | Banco Pichincha C.A. landscape | IcePanel App | AT21: https://dev.azure.com/BancoPichinchaEC/adi-especificaciones-tecnicas/_git/adi-doc-tecspec-tribu-integracion-apis?version=GBmaster&path=/sp%20-%20Soporte/tnd-msa-sp-orqclientes0037 | AU21: https://BancoPichinchaEC@dev.azure.com/BancoPichinchaEC/tpl-bus-omnicanal/_git/sqb-msa-orqclientes0037 | AV21: 1 | AW21: https://pichincha.atlassian.net/browse/PCBG-600
